Workbook

Sheet INVENTARIO
B1: INVENTARIO DE PAÑOL
B2: REFERENCIA | C2: DESCRIPCIÓN DE PRODUCTO | D2: EQUIPO DONDE SE APLICA | E2: DISPONIBLES | F2: DETALLE | G2: TIPO
B3: CAD-40-Simple | C3: ASA 40 simple | D3: en varias maq-
B4: CAD-50-Simple | C4: ASA 50 simple | D4: trasp-horno
B5: CAD-S55 | C5: ASA S55 simple | D5: estivador L-GA3000
B6: CAD-50 Doble | C6: ASA 50 doble | D6: trasp-horno
B7: CAD-SS50 | C7: ASA 50 simple inoxidable | D7: transp-salida horno
B8: CAD-S60 Doble | C8: ASA 60 DOBLE | D8: armadora-horno
B9: CAD-S60 Simple | C9: 60-simple | D9: laminadores en tapas
B10: CAD-ASA80X2 | C10: cadena ASA 80 doble | D10: amasadora
B11: CAD-06B-2 | C11: 06-B2 doble | D11: divisora L-GA3000
B12: CAD- 06-Simple | C12: 06-B1 simple | D12: cinta -mesa de apile (tapas)
B13: Medio Union Cad 06B1 (simple) | C13: Medio eslabon
B14: Medio Union Cad 06B1 (doble) | C14: Medio eslabon
B15: Union Cad 06B1 (simple) | C15: Union 06B1
B16: Union Cad 06B2 (doble) | C16: Union 06B2 | D16: maq-jake
B17: MED-UNI-CAD-40X1 | C17: Medio eslabon | D17: maq- divis-imepa | E17: 15
B18: UNI-CAD-40X1 | C18: union cadena 40 simple | D18: varias maq- | E18: 20
B19: UNI-CAD-40X1 C/ALTEA | C19: Union cadena ASA 40 con ALETA LATERAL | D19: Embolsadora salida rebanadora | E19: 50
B20: Union cad 50 | C20: Medio eslabon | D20: divisora L-GA3000
B21: UNI-CAD-50Simple | C21: Union cad 50 simple
B22: UNI-CAD-50Simple | C22: union cadena ASA 50 doble
B23: UNI-CAD-60 Simple | C23: Union cad ASA 60 simple
B24: UNI-CAD-60-Doble | C24: Union cadena ASA 60 doble
B25: MED-CAD-60-Doble | C25: Medio Eslab.ASA 60 doble
B26: Union cad ASA 80-Doble | C26: Medio eslabon ASA80 | D26: Horno-Armadora de tapas
B27: UN-CAD-80X2 | C27: union cadena ASA 80 doble | D27: amasadora
B28: CAD-120 Doble | C28: Cadena ASA 120 Doble | D28: Enfriador
B29: MED-CAD-120 Doble | C29: Medio Eslabon Cadena ASA 120 Doble | D29: Enfriador
B30: Union-CAD-120 Doble | C30: Union Cadena ASA 120 doble | D30: Enfriador
B31: Union Cad S55 | C31: S55 Union | D31: Estibador
B32: MED-Union Cad S55 | C32: S55 medio eslabon | D32: Estibador
B33: PERNOS -ESTIBA | C33: Pernos Para Bandejas Estibador | D33: Estibador L-GA3000 | E33: 14
B34: ROD- CF1 1/8 S | C34: CF 1 1/8 S | D34: LEVA ENBOLS-AMF | E34: 5
B35: ROD-UCT208 | C35: UCT208 | D35: banda desmoldador
B36: ROD-GY1103KRRB3 | C36: GY1103KRRB3
B37: ROD-UL211-200 | C37: UL211-200
B38: ROD-UC203 | C38: UC203 | E38: 14
B39: ROD-UC206-20 | C39: UC206-20 EJE 31,74
B40: ROD-UC206 | C40: UC206-EJE 30 | D40: L-GA3000 | E40: 5
...

Sheet Hoja 7
B1: INVENTARIO
B2: REFERENCIA | C2: DESCRIPCIÓN DE PRODUCTO | D2: EQUIPO DONDE SE APLICA | E2: DISPONIBLE | F2: DETALLE | G2: TIPO
B3: CAD-40-Simple
B4: CAD-50-Simple
B5: CAD-S55
B6: CAD-50 Doble
B7: CAD-SS50
B8: CAD-S6O Doble
B9: CAD-S60 Simple
B10: CAD-ASA80X2
B11: CAD-06B-2
B12: CAD- 06-Simple
B13: Medio Union Cad 06B1 (simple)

Sheet ENTRADAS
B2: REFERENCIA | C2: NOMBRE | D2: UNIDADES | E2: COSTO UNIDAD | F2: FECHA
B4: CAD-40 | C4: =IFERROR(VLOOKUP(B4 ,INVENTARIO!$B$2:C994,2,0),"") | D4: 2.5 | F4: =IFS(B4="","",F4<>"",F4,TRUE,NOW()) -> 45659.58
B5: CAD-S55 | C5: =IFERROR(VLOOKUP(B5 ,INVENTARIO!$B$2:C994,2,0),"") -> ASA S55 simple | D5: 1.5 | F5: =IFS(B5="","",F5<>"",F5,TRUE,NOW()) -> 45659.58
B6: CAD-50 Doble | C6: =IFERROR(VLOOKUP(B6 ,INVENTARIO!$B$2:C994,2,0),"") -> ASA 50 doble | D6: 8.7 | F6: =IFS(B6="","",F6<>"",F6,TRUE,NOW()) -> 45659.582
B7: CAD-SS50 | C7: =IFERROR(VLOOKUP(B7 ,INVENTARIO!$B$2:C994,2,0),"") -> ASA 50 simple inoxidable | D7: 0.6 | F7: =IFS(B7="","",F7<>"",F7,TRUE,NOW()) -> 45659.583
B8: CAD-S60 Doble | C8: =IFERROR(VLOOKUP(B8 ,INVENTARIO!$B$2:C994,2,0),"") -> ASA 60 DOBLE | D8: 9.8 | F8: =IFS(B8="","",F8<>"",F8,TRUE,NOW()) -> 45660.47
B9: CAD-60-1 | C9: =IFERROR(VLOOKUP(B9 ,INVENTARIO!$B$2:C994,2,0),"") | D9: 10 | F9: =IFS(B9="","",F9<>"",F9,TRUE,NOW()) -> 45660.471
B10: CAD-80X2 | C10: =IFERROR(VLOOKUP(B10 ,INVENTARIO!$B$2:C994,2,0),"") | D10: 3.86 | F10: =IFS(B10="","",F10<>"",F10,TRUE,NOW()) -> 45660.472
B11: CAD-40-Simple | C11: =IFERROR(VLOOKUP(B11 ,INVENTARIO!$B$2:C994,2,0),"") -> ASA 40 simple | D11: 4.65 | F11: =IFS(B11="","",F11<>"",F11,TRUE,NOW()) -> 45660.473
B12: BAN-ELEV | C12: =IFERROR(VLOOKUP(B12 ,INVENTARIO!$B$2:C994,2,0),"") -> 400X2500mm x2 | D12: 5 | F12: =IFS(B12="","",F12<>"",F12,TRUE,NOW()) -> 45660.475
B13: Union Cad 06B1 (simple) | C13: =IFERROR(VLOOKUP(B13 ,INVENTARIO!$B$2:C994,2,0),"") -> Union 06B1 | D13: 7 | F13: =IFS(B13="","",F13<>"",F13,TRUE,NOW()) -> 45660.635
B14: Union Cad 06B2 (doble) | C14: =IFERROR(VLOOKUP(B14 ,INVENTARIO!$B$2:C994,2,0),"") -> Union 06B2 | D14: 16 | F14: =IFS(B14="","",F14<>"",F14,TRUE,NOW()) -> 45660.635
B15: MED-UNI-CAD-40X1 | C15: =IFERROR(VLOOKUP(B15 ,INVENTARIO!$B$2:C994,2,0),"") -> Medio eslabon | D15: 8 | F15: =IFS(B15="","",F15<>"",F15,TRUE,NOW()) -> 45660.636
B16: UNI-CAD-40X1 C/ALTEA | C16: =IFERROR(VLOOKUP(B16 ,INVENTARIO!$B$2:C994,2,0),"") -> Union cadena ASA 40 con ALETA LATERAL | D16: 23 | F16: =IFS(B16="","",F16<>"",F16,TRUE,NOW()) -> 45660.637
B17: Union cad 50 | C17: =IFERROR(VLOOKUP(B17 ,INVENTARIO!$B$2:C994,2,0),"") -> Medio eslabon | D17: 14 | F17: =IFS(B17="","",F17<>"",F17,TRUE,NOW()) -> 45660.638
B18: UNI-CAD-50Simple | C18: =IFERROR(VLOOKUP(B18 ,INVENTARIO!$B$2:C994,2,0),"") -> Union cad 50 simple | D18: 7 | F18: =IFS(B18="","",F18<>"",F18,TRUE,NOW()) -> 45660.638
B19: UNI-CAD-50X2 | C19: =IFERROR(VLOOKUP(B19 ,INVENTARIO!$B$2:C994,2,0),"") | D19: 13 | F19: =IFS(B19="","",F19<>"",F19,TRUE,NOW()) -> 45660.639
B20: UNI-CAD-60X2 | C20: =IFERROR(VLOOKUP(B20 ,INVENTARIO!$B$2:C994,2,0),"") | D20: 27 | F20: =IFS(B20="","",F20<>"",F20,TRUE,NOW()) -> 45660.639
B21: CAD-80X2 | C21: =IFERROR(VLOOKUP(B21 ,INVENTARIO!$B$2:C994,2,0),"") | D21: 12 | F21: =IFS(B21="","",F21<>"",F21,TRUE,NOW()) -> 45660.64
B22: CAD-120 Doble | C22: =IFERROR(VLOOKUP(B22 ,INVENTARIO!$B$2:C994,2,0),"") -> Cadena ASA 120 Doble | D22: 1 | F22: =IFS(B22="","",F22<>"",F22,TRUE,NOW()) -> 45660.64
B23: MED-CAD-120 Doble | C23: =IFERROR(VLOOKUP(B23 ,INVENTARIO!$B$2:C994,2,0),"") -> Medio Eslabon Cadena ASA 120 Doble | D23: 1 | F23: =IFS(B23="","",F23<>"",F23,TRUE,NOW()) -> 45660.641
B24: MED-Union Cad S55 | C24: =IFERROR(VLOOKUP(B24 ,INVENTARIO!$B$2:C994,2,0),"") -> S55 medio eslabon | D24: 4 | F24: =IFS(B24="","",F24<>"",F24,TRUE,NOW()) -> 45660.642
B25: PERNOS -ESTIBA | C25: =IFERROR(VLOOKUP(B25 ,INVENTARIO!$B$2:C994,2,0),"") -> Pernos Para Bandejas Estibador | D25: 6 | F25: =IFS(B25="","",F25<>"",F25,TRUE,NOW()) -> 45660.642
B26: ROD- CF1 1/8 S | C26: =IFERROR(VLOOKUP(B26 ,INVENTARIO!$B$2:C994,2,0),"") -> CF 1 1/8 S | D26: 4 | F26: =IFS(B26="","",F26<>"",F26,TRUE,NOW()) -> 45660.642
B27: ROD-UCT208 | C27: =IFERROR(VLOOKUP(B27 ,INVENTARIO!$B$2:C994,2,0),"") -> UCT208 | D27: 2 | F27: =IFS(B27="","",F27<>"",F27,TRUE,NOW()) -> 45660.643
B28: ROD-GY1103KRRB3 | C28: =IFERROR(VLOOKUP(B28 ,INVENTARIO!$B$2:C994,2,0),"") -> GY1103KRRB3 | D28: 2 | F28: =IFS(B28="","",F28<>"",F28,TRUE,NOW()) -> 45660.643
B29: ROD-UL211-200 | C29: =IFERROR(VLOOKUP(B29 ,INVENTARIO!$B$2:C994,2,0),"") -> UL211-200 | D29: 3 | F29: =IFS(B29="","",F29<>"",F29,TRUE,NOW()) -> 45660.685
B30: ROD-UC203 | C30: =IFERROR(VLOOKUP(B30 ,INVENTARIO!$B$2:C994,2,0),"") -> UC203 | D30: 7 | F30: =IFS(B30="","",F30<>"",F30,TRUE,NOW()) -> 45660.686
B31: ROD-UC206-20 | C31: =IFERROR(VLOOKUP(B31 ,INVENTARIO!$B$2:C994,2,0),"") -> UC206-20 EJE 31,74 | D31: 20 | F31: =IFS(B31="","",F31<>"",F31,TRUE,NOW()) -> 45660.686
B32: ROD-UC206 | C32: =IFERROR(VLOOKUP(B32 ,INVENTARIO!$B$2:C994,2,0),"") -> UC206-EJE 30 | D32: 13 | F32: =IFS(B32="","",F32<>"",F32,TRUE,NOW()) -> 45660.686
B33: ROD-UC206-104D1 | C33: =IFERROR(VLOOKUP(B33 ,INVENTARIO!$B$2:C994,2,0),"") -> UC206-104D1 | D33: 5 | F33: =IFS(B33="","",F33<>"",F33,TRUE,NOW()) -> 45660.687
B34: ROD-AEL206 | C34: =IFERROR(VLOOKUP(B34 ,INVENTARIO!$B$2:C994,2,0),"") -> AEL206-104D1 | D34: 4 | F34: =IFS(B34="","",F34<>"",F34,TRUE,NOW()) -> 45661.576
B35: ROD-UC206-G | C35: =IFERROR(VLOOKUP(B35 ,INVENTARIO!$B$2:C994,2,0),"") -> UC206G | D35: 4 | F35: =IFS(B35="","",F35<>"",F35,TRUE,NOW()) -> 45661.576
B36: ROD-UC204D1 | C36: =IFERROR(VLOOKUP(B36 ,INVENTARIO!$B$2:C994,2,0),"") -> UC204D1 | D36: 2 | F36: =IFS(B36="","",F36<>"",F36,TRUE,NOW()) -> 45661.576
B37: ROD-AS204D1 | C37: =IFERROR(VLOOKUP(B37 ,INVENTARIO!$B$2:C994,2,0),"") -> AS204D1 | D37: 2 | F37: =IFS(B37="","",F37<>"",F37,TRUE,NOW()) -> 45661.577
B38: ROD-UC203 | C38: =IFERROR(VLOOKUP(B38 ,INVENTARIO!$B$2:C994,2,0),"") -> UC203 | D38: 2 | F38: =IFS(B38="","",F38<>"",F38,TRUE,NOW()) -> 45661.578
B39: ROD-UC202-010D1 | C39: =IFERROR(VLOOKUP(B39 ,INVENTARIO!$B$2:C994,2,0),"") -> UC202-010D1 | D39: 10 | F39: =IFS(B39="","",F39<>"",F39,TRUE,NOW()) -> 45661.578
B40: ROD-UC211 | C40: =IFERROR(VLOOKUP(B40 ,INVENTARIO!$B$2:C994,2,0),"") -> UC211-200D1 | D40: 6 | F40: =IFS(B40="","",F40<>"",F40,TRUE,NOW()) -> 45661.579
B41: ROD-UC212 | C41: =IFERROR(VLOOKUP(B41 ,INVENTARIO!$B$2:C994,2,0),"") -> UC212D1 | D41: 2 | F41: =IFS(B41="","",F41<>"",F41,TRUE,NOW()) -> 45661.579
B42: ROD-UC205 | C42: =IFERROR(VLOOKUP(B42 ,INVENTARIO!$B$2:C994,2,0),"") -> UC205 | D42: 1 | F42: =IFS(B42="","",F42<>"",F42,TRUE,NOW()) -> 45661.579
...

Sheet SALIDAS
B2: REFERENCIA | C2: NOMBRE | D2: Cantidad de artículos a descargar | E2: Disponible en stock | F2: FECHA | G2: TÉCNICO
B3: ROD-6202-2RS | D3: 8 | F3: =IFS(B3="","",F3<>"",F3,TRUE,NOW()) -> 45670.578
B4: BANC-P211 | C4: =IFERROR(VLOOKUP(B4 ,INVENTARIO!$B$2:C996,2,0),"") -> P211 | D4: 1 | F4: =IFS(B4="","",F4<>"",F4,TRUE,NOW()) -> 45678.873
B5: ROD-6205 | C5: =IFERROR(VLOOKUP(B5 ,INVENTARIO!$B$2:C996,2,0),"") -> 6205-2RST/C3 | D5: 2 | F5: =IFS(B5="","",F5<>"",F5,TRUE,NOW()) -> 45680.557
B6: ret- 25-37-7 | C6: =IFERROR(VLOOKUP(B6 ,INVENTARIO!$B$2:C996,2,0),"") | D6: 2 | F6: =IFS(B6="","",F6<>"",F6,TRUE,NOW()) -> 45680.59
B7: ROD-6203 | C7: =IFERROR(VLOOKUP(B7 ,INVENTARIO!$B$2:C996,2,0),"") -> 6203 2RST/C3 | D7: 1 | F7: =IFS(B7="","",F7<>"",F7,TRUE,NOW()) -> 45680.594
B8: ROD-UC204D1 | C8: =IFERROR(VLOOKUP(B8 ,INVENTARIO!$B$2:C996,2,0),"") -> UC204D1 | D8: 1 | F8: =IFS(B8="","",F8<>"",F8,TRUE,NOW()) -> 45680.805
B9: ROD- 6903 | C9: 69032rs | D9: 2 | F9: =IFS(B9="","",F9<>"",F9,TRUE,NOW()) -> 45680.806
B10: ROD-UC205 | C10: =IFERROR(VLOOKUP(B10 ,INVENTARIO!$B$2:C996,2,0),"") -> UC205 | D10: 1 | F10: =IFS(B10="","",F10<>"",F10,TRUE,NOW()) -> 45694.685
B11: RET- 5427 | C11: =IFERROR(VLOOKUP(B11 ,INVENTARIO!$B$2:C996,2,0),"") -> 35-47-7 | F11: =IFS(B11="","",F11<>"",F11,TRUE,NOW()) -> 45695.676
B12: ROD-UC204D1 | C12: =IFERROR(VLOOKUP(B12 ,INVENTARIO!$B$2:C996,2,0),"") -> UC204D1 | D12: 1 | F12: =IFS(B12="","",F12<>"",F12,TRUE,NOW()) -> 45702.364
B13: ROD-UC204D1 | C13: =IFERROR(VLOOKUP(B13 ,INVENTARIO!$B$2:C996,2,0),"") -> UC204D1 | D13: 2 | F13: =IFS(B13="","",F13<>"",F13,TRUE,NOW()) -> 45707.333
B14: ROD- 6903 | C14: =IFERROR(VLOOKUP(B14 ,INVENTARIO!$B$2:C996,2,0),"") -> 6903 | D14: 2 | F14: =IFS(B14="","",F14<>"",F14,TRUE,NOW()) -> 45707.337
B15: ROD-1209 | C15: =IFERROR(VLOOKUP(B15 ,INVENTARIO!$B$2:C996,2,0),"") | D15: 2 | F15: =IFS(B15="","",F15<>"",F15,TRUE,NOW()) -> 45713.361
B16: ROD-1621 | C16: =IFERROR(VLOOKUP(B16 ,INVENTARIO!$B$2:C996,2,0),"") -> 1621DCTNTG18 | D16: 4 | F16: =IFS(B16="","",F16<>"",F16,TRUE,NOW()) -> 45714.548
B17: ROD-6206 | C17: =IFERROR(VLOOKUP(B17 ,INVENTARIO!$B$2:C996,2,0),"") -> 6206LLUC3 6206 LLUC3/2AS | D17: 1 | F17: =IFS(B17="","",F17<>"",F17,TRUE,NOW()) -> 45714.55
B18: ROD-6209 | C18: =IFERROR(VLOOKUP(B18 ,INVENTARIO!$B$2:C996,2,0),"") -> 6209LLUC3 6209LLUC3/2AS | D18: 1 | F18: =IFS(B18="","",F18<>"",F18,TRUE,NOW()) -> 45717.843
B19: RET- 5462 | C19: =IFERROR(VLOOKUP(B19 ,INVENTARIO!$B$2:C996,2,0),"") | D19: 1 | F19: =IFS(B19="","",F19<>"",F19,TRUE,NOW()) -> 45718.335
B20: ROD-6004 | C20: =IFERROR(VLOOKUP(B20 ,INVENTARIO!$B$2:C996,2,0),"") -> 6004-2RST/C3 | D20: 2 | F20: =IFS(B20="","",F20<>"",F20,TRUE,NOW()) -> 45719.264
B21: ROD-6005 | C21: =IFERROR(VLOOKUP(B21 ,INVENTARIO!$B$2:C996,2,0),"") -> 6005LLUC3/ 6005LLUC3/2AS | D21: 6 | F21: =IFS(B21="","",F21<>"",F21,TRUE,NOW()) -> 45719.264
B22: COR-240XL | C22: =IFERROR(VLOOKUP(B22 ,INVENTARIO!$B$2:C996,2,0),"") -> CORREA DENTADA 240XL Transferencia | D22: 1 | F22: =IFS(B22="","",F22<>"",F22,TRUE,NOW()) -> 45719.265
B23: COR-B47 | C23: =IFERROR(VLOOKUP(B23 ,INVENTARIO!$B$2:C996,2,0),"") -> Correas B-47 | D23: 2 | F23: =IFS(B23="","",F23<>"",F23,TRUE,NOW()) -> 45719.266
B24: RET-50-65-10 | C24: =IFERROR(VLOOKUP(B24 ,INVENTARIO!$B$2:C996,2,0),"") | D24: 2 | F24: =IFS(B24="","",F24<>"",F24,TRUE,NOW()) -> 45719.642
B25: ROD-6201 | C25: =IFERROR(VLOOKUP(B25 ,INVENTARIO!$B$2:C996,2,0),"") -> 6201LLUC3/2RS | D25: 1 | F25: =IFS(B25="","",F25<>"",F25,TRUE,NOW()) -> 45723.52
B26: ROD-6002 | C26: =IFERROR(VLOOKUP(B26 ,INVENTARIO!$B$2:C996,2,0),"") | D26: 1 | F26: =IFS(B26="","",F26<>"",F26,TRUE,NOW()) -> 45723.521
B27: MAN-MM40-35 | C27: =IFERROR(VLOOKUP(B2),"") | D27: 2 | F27: =IFS(B27="","",F27<>"",F27,TRUE,NOW()) -> 45724.449
B28: FIL-REG- | C28: =IFERROR(VLOOKUP(B28 ,INVENTARIO!$B$2:C996,2,0),"") -> filtro regulador con manometro | D28: 1 | F28: =IFS(B28="","",F28<>"",F28,TRUE,NOW()) -> 45724.45
B29: ROD-6304 | C29: =IFERROR(VLOOKUP(B29 ,INVENTARIO!$B$2:C996,2,0),"") -> 6304/2RS-C3 | D29: 1 | F29: =IFS(B29="","",F29<>"",F29,TRUE,NOW()) -> 45727.506
B30: ROD-6800 | C30: =IFERROR(VLOOKUP(B30 ,INVENTARIO!$B$2:C996,2,0),"") -> 6800LLU | D30: 2 | F30: =IFS(B30="","",F30<>"",F30,TRUE,NOW()) -> 45728.583
B31: RET-7297 | C31: =IFERROR(VLOOKUP(B31 ,INVENTARIO!$B$2:C996,2,0),"") -> DBH 8233 / 45-65-10 | D31: 2 | F31: =IFS(B31="","",F31<>"",F31,TRUE,NOW()) -> 45729.665
B32: ROD- 6003 | C32: =IFERROR(VLOOKUP(B32 ,INVENTARIO!$B$2:C996,2,0),"") -> 6003 LLU/C3 - 17X35X10 | D32: 4 | F32: =IFS(B32="","",F32<>"",F32,TRUE,NOW()) -> 45731.284
B33: ROD-6307 | C33: =IFERROR(VLOOKUP(B33 ,INVENTARIO!$B$2:C996,2,0),"") -> 6307 2RS | D33: 2 | F33: =IFS(B33="","",F33<>"",F33,TRUE,NOW()) -> 45733.438
B34: ROD-UC205 | C34: =IFERROR(VLOOKUP(B34 ,INVENTARIO!$B$2:C996,2,0),"") -> UC205 | D34: 2 | F34: =IFS(B34="","",F34<>"",F34,TRUE,NOW()) -> 45734.448
B35: RET-1134 | C35: =IFERROR(VLOOKUP(B35 ,INVENTARIO!$B$2:C996,2,0),"") -> 24-42-8 | D35: 2 | F35: =IFS(B35="","",F35<>"",F35,TRUE,NOW()) -> 45734.456
B36: ROD-UC204D1 | C36: =IFERROR(VLOOKUP(B36 ,INVENTARIO!$B$2:C996,2,0),"") -> UC204D1 | D36: 2 | F36: =IFS(B36="","",F36<>"",F36,TRUE,NOW()) -> 45735.688
B37: ROD-6201 | C37: =IFERROR(VLOOKUP(B37 ,INVENTARIO!$B$2:C996,2,0),"") -> 6201LLUC3/2RS | D37: 2 | F37: =IFS(B37="","",F37<>"",F37,TRUE,NOW()) -> 45736.413
B38: COR-240XL | C38: =IFERROR(VLOOKUP(B38 ,INVENTARIO!$B$2:C996,2,0),"") -> CORREA DENTADA 240XL Transferencia | D38: 6 | F38: =IFS(B38="","",F38<>"",F38,TRUE,NOW()) -> 45736.43
B39: ROD-UC204D1 | C39: =IFERROR(VLOOKUP(B39 ,INVENTARIO!$B$2:C996,2,0),"") -> UC204D1 | D39: 2 | F39: =IFS(B39="","",F39<>"",F39,TRUE,NOW()) -> 45737.576
B40: RED-ALFA NMRV040 | C40: =IFERROR(VLOOKUP(B40 ,INVENTARIO!$B$2:C996,2,0),"") -> R-7,5 Nuevo | D40: 1 | F40: =IFS(B40="","",F40<>"",F40,TRUE,NOW()) -> 45737.618
B41: RET- 7213 | C41: =IFERROR(VLOOKUP(B41 ,INVENTARIO!$B$2:C996,2,0),"") -> RET-45-75-8 | D41: 1 | F41: =IFS(B41="","",F41<>"",F41,TRUE,NOW()) -> 45737.882
...

Sheet TOTALES
B2: REFERENCIA | C2: NOMBRE | D2: ENTRADAS | E2: SALIDAS | F2: RESTO | G2: VALOR ENTRADAS | H2: VALOR SALIDAS
B3: {=UNIQUE(ENTRADAS!B4:B1000)} -> CAD-40 | C3: =IFERROR(VLOOKUP(B3 ,INVENTARIO!B2:C1000,2,0),"") | D3: =SUMIF(ENTRADAS!B:B,B3,ENTRADAS!D:D) -> 11.5 | E3: =SUMIF(SALIDAS!B:B,B3,SALIDAS!D:D) -> 0 | F3: =SUM(D3-E3) -> 11.5
B4: CAD-S55 | C4: =IFERROR(VLOOKUP(B4 ,INVENTARIO!B3:C1000,2,0),"") -> ASA S55 simple | D4: =SUMIF(ENTRADAS!B:B,B4,ENTRADAS!D:D) -> 1.5 | E4: =SUMIF(SALIDAS!B:B,B4,SALIDAS!D:D) -> 0 | F4: =SUM(D4-E4) -> 1.5
B5: CAD-50 Doble | C5: =IFERROR(VLOOKUP(B5 ,INVENTARIO!B4:C1000,2,0),"") -> ASA 50 doble | D5: =SUMIF(ENTRADAS!B:B,B5,ENTRADAS!D:D) -> 8.7 | E5: =SUMIF(SALIDAS!B:B,B5,SALIDAS!D:D) -> 0 | F5: =SUM(D5-E5) -> 8.7
B6: CAD-SS50 | C6: =IFERROR(VLOOKUP(B6 ,INVENTARIO!B5:C1000,2,0),"") -> ASA 50 simple inoxidable | D6: =SUMIF(ENTRADAS!B:B,B6,ENTRADAS!D:D) -> 0.6 | E6: =SUMIF(SALIDAS!B:B,B6,SALIDAS!D:D) -> 0 | F6: =SUM(D6-E6) -> 0.6
B7: CAD-S60 Doble | C7: =IFERROR(VLOOKUP(B7 ,INVENTARIO!B6:C1000,2,0),"") -> ASA 60 DOBLE | D7: =SUMIF(ENTRADAS!B:B,B7,ENTRADAS!D:D) -> 9.8 | E7: =SUMIF(SALIDAS!B:B,B7,SALIDAS!D:D) -> 2 | F7: =SUM(D7-E7) -> 7.8
B8: CAD-60-1 | C8: =IFERROR(VLOOKUP(B8 ,INVENTARIO!B7:C1000,2,0),"") | D8: =SUMIF(ENTRADAS!B:B,B8,ENTRADAS!D:D) -> 12 | E8: =SUMIF(SALIDAS!B:B,B8,SALIDAS!D:D) -> 0 | F8: =SUM(D8-E8) -> 12
B9: CAD-80X2 | C9: =IFERROR(VLOOKUP(B9 ,INVENTARIO!B8:C1000,2,0),"") | D9: =SUMIF(ENTRADAS!B:B,B9,ENTRADAS!D:D) -> 15.86 | E9: =SUMIF(SALIDAS!B:B,B9,SALIDAS!D:D) -> 0 | F9: =SUM(D9-E9) -> 15.86
B10: CAD-40-Simple | C10: =IFERROR(VLOOKUP(B10 ,INVENTARIO!B9:C1000,2,0),"") | D10: =SUMIF(ENTRADAS!B:B,B10,ENTRADAS!D:D) -> 4.65 | E10: =SUMIF(SALIDAS!B:B,B10,SALIDAS!D:D) -> 0 | F10: =SUM(D10-E10) -> 4.65
B11: BAN-ELEV | C11: =IFERROR(VLOOKUP(B11 ,INVENTARIO!B10:C1000,2,0),"") -> 400X2500mm x2 | D11: =SUMIF(ENTRADAS!B:B,B11,ENTRADAS!D:D) -> 6 | E11: =SUMIF(SALIDAS!B:B,B11,SALIDAS!D:D) -> 0 | F11: =SUM(D11-E11) -> 6
B12: Union Cad 06B1 (simple) | C12: =IFERROR(VLOOKUP(B12 ,INVENTARIO!B11:C1000,2,0),"") -> Union 06B1 | D12: =SUMIF(ENTRADAS!B:B,B12,ENTRADAS!D:D) -> 7 | E12: =SUMIF(SALIDAS!B:B,B12,SALIDAS!D:D) -> 0 | F12: =SUM(D12-E12) -> 7
B13: Union Cad 06B2 (doble) | C13: =IFERROR(VLOOKUP(B13 ,INVENTARIO!B12:C1000,2,0),"") -> Union 06B2 | D13: =SUMIF(ENTRADAS!B:B,B13,ENTRADAS!D:D) -> 16 | E13: =SUMIF(SALIDAS!B:B,B13,SALIDAS!D:D) -> 0 | F13: =SUM(D13-E13) -> 16
B14: MED-UNI-CAD-40X1 | C14: =IFERROR(VLOOKUP(B14 ,INVENTARIO!B13:C1000,2,0),"") -> Medio eslabon | D14: =SUMIF(ENTRADAS!B:B,B14,ENTRADAS!D:D) -> 8 | E14: =SUMIF(SALIDAS!B:B,B14,SALIDAS!D:D) -> 0 | F14: =SUM(D14-E14) -> 8
B15: UNI-CAD-40X1 C/ALTEA | C15: =IFERROR(VLOOKUP(B15 ,INVENTARIO!B14:C1000,2,0),"") -> Union cadena ASA 40 con ALETA LATERAL | D15: =SUMIF(ENTRADAS!B:B,B15,ENTRADAS!D:D) -> 23 | E15: =SUMIF(SALIDAS!B:B,B15,SALIDAS!D:D) -> 0 | F15: =SUM(D15-E15) -> 23
B16: Union cad 50 | C16: =IFERROR(VLOOKUP(B16 ,INVENTARIO!B15:C1000,2,0),"") -> Medio eslabon | D16: =SUMIF(ENTRADAS!B:B,B16,ENTRADAS!D:D) -> 14 | E16: =SUMIF(SALIDAS!B:B,B16,SALIDAS!D:D) -> 0 | F16: =SUM(D16-E16) -> 14
B17: UNI-CAD-50Simple | C17: =IFERROR(VLOOKUP(B17 ,INVENTARIO!B16:C1000,2,0),"") -> Union cad 50 simple | D17: =SUMIF(ENTRADAS!B:B,B17,ENTRADAS!D:D) -> 7 | E17: =SUMIF(SALIDAS!B:B,B17,SALIDAS!D:D) -> 0 | F17: =SUM(D17-E17) -> 7
B18: UNI-CAD-50X2 | C18: =IFERROR(VLOOKUP(B18 ,INVENTARIO!B17:C1000,2,0),"") | D18: =SUMIF(ENTRADAS!B:B,B18,ENTRADAS!D:D) -> 13 | E18: =SUMIF(SALIDAS!B:B,B18,SALIDAS!D:D) -> 0 | F18: =SUM(D18-E18) -> 13
B19: UNI-CAD-60X2 | C19: =IFERROR(VLOOKUP(B19 ,INVENTARIO!B18:C1000,2,0),"") | D19: =SUMIF(ENTRADAS!B:B,B19,ENTRADAS!D:D) -> 27 | E19: =SUMIF(SALIDAS!B:B,B19,SALIDAS!D:D) -> 0 | F19: =SUM(D19-E19) -> 27
B20: CAD-120 Doble | C20: =IFERROR(VLOOKUP(B20 ,INVENTARIO!B20:C1000,2,0),"") -> Cadena ASA 120 Doble | D20: =SUMIF(ENTRADAS!B:B,B20,ENTRADAS!D:D) -> 2 | E20: =SUMIF(SALIDAS!B:B,B20,SALIDAS!D:D) -> 0 | F20: =SUM(D20-E20) -> 2
B21: MED-CAD-120 Doble | C21: =IFERROR(VLOOKUP(B21 ,INVENTARIO!B21:C1000,2,0),"") -> Medio Eslabon Cadena ASA 120 Doble | D21: =SUMIF(ENTRADAS!B:B,B21,ENTRADAS!D:D) -> 3 | E21: =SUMIF(SALIDAS!B:B,B21,SALIDAS!D:D) -> 0 | F21: =SUM(D21-E21) -> 3
B22: MED-Union Cad S55 | C22: =IFERROR(VLOOKUP(B22 ,INVENTARIO!B22:C1000,2,0),"") -> S55 medio eslabon | D22: =SUMIF(ENTRADAS!B:B,B22,ENTRADAS!D:D) -> 4 | E22: =SUMIF(SALIDAS!B:B,B22,SALIDAS!D:D) -> 0 | F22: =SUM(D22-E22) -> 4
B23: PERNOS -ESTIBA | C23: =IFERROR(VLOOKUP(B23 ,INVENTARIO!B23:C1000,2,0),"") -> Pernos Para Bandejas Estibador | D23: =SUMIF(ENTRADAS!B:B,B23,ENTRADAS!D:D) -> 6 | E23: =SUMIF(SALIDAS!B:B,B23,SALIDAS!D:D) -> 1 | F23: =SUM(D23-E23) -> 5
B24: ROD- CF1 1/8 S | C24: =IFERROR(VLOOKUP(B24 ,INVENTARIO!B24:C1000,2,0),"") -> CF 1 1/8 S | D24: =SUMIF(ENTRADAS!B:B,B24,ENTRADAS!D:D) -> 4 | E24: =SUMIF(SALIDAS!B:B,B24,SALIDAS!D:D) -> 1 | F24: =SUM(D24-E24) -> 3
B25: ROD-UCT208 | C25: =IFERROR(VLOOKUP(B25 ,INVENTARIO!B26:C1000,2,0),"") -> UCT208 | D25: =SUMIF(ENTRADAS!B:B,B25,ENTRADAS!D:D) -> 2 | E25: =SUMIF(SALIDAS!B:B,B25,SALIDAS!D:D) -> 0 | F25: =SUM(D25-E25) -> 2
B26: ROD-GY1103KRRB3 | C26: =IFERROR(VLOOKUP(B26 ,INVENTARIO!B27:C1000,2,0),"") -> GY1103KRRB3 | D26: =SUMIF(ENTRADAS!B:B,B26,ENTRADAS!D:D) -> 2 | E26: =SUMIF(SALIDAS!B:B,B26,SALIDAS!D:D) -> 0 | F26: =SUM(D26-E26) -> 2
B27: ROD-UL211-200 | C27: =IFERROR(VLOOKUP(B27 ,INVENTARIO!B28:C1000,2,0),"") -> UL211-200 | D27: =SUMIF(ENTRADAS!B:B,B27,ENTRADAS!D:D) -> 3 | E27: =SUMIF(SALIDAS!B:B,B27,SALIDAS!D:D) -> 0 | F27: =SUM(D27-E27) -> 3
B28: ROD-UC203 | C28: =IFERROR(VLOOKUP(B28 ,INVENTARIO!B29:C1000,2,0),"") -> UC203 | D28: =SUMIF(ENTRADAS!B:B,B28,ENTRADAS!D:D) -> 9 | E28: =SUMIF(SALIDAS!B:B,B28,SALIDAS!D:D) -> 0 | F28: =SUM(D28-E28) -> 9
B29: ROD-UC206-20 | C29: =IFERROR(VLOOKUP(B29 ,INVENTARIO!B31:C1000,2,0),"") -> UC206-20 EJE 31,74 | D29: =SUMIF(ENTRADAS!B:B,B29,ENTRADAS!D:D) -> 20 | E29: =SUMIF(SALIDAS!B:B,B29,SALIDAS!D:D) -> 0 | F29: =SUM(D29-E29) -> 20
B30: ROD-UC206 | C30: =IFERROR(VLOOKUP(B30 ,INVENTARIO!B32:C1000,2,0),"") -> UC206-EJE 30 | D30: =SUMIF(ENTRADAS!B:B,B30,ENTRADAS!D:D) -> 15 | E30: =SUMIF(SALIDAS!B:B,B30,SALIDAS!D:D) -> 3 | F30: =SUM(D30-E30) -> 12
B31: ROD-UC206-104D1 | C31: =IFERROR(VLOOKUP(B31 ,INVENTARIO!B33:C1000,2,0),"") -> UC206-104D1 | D31: =SUMIF(ENTRADAS!B:B,B31,ENTRADAS!D:D) -> 5 | E31: =SUMIF(SALIDAS!B:B,B31,SALIDAS!D:D) -> 0 | F31: =SUM(D31-E31) -> 5
B32: ROD-AEL206 | C32: =IFERROR(VLOOKUP(B32 ,INVENTARIO!B34:C1000,2,0),"") -> AEL206-104D1 | D32: =SUMIF(ENTRADAS!B:B,B32,ENTRADAS!D:D) -> 4 | E32: =SUMIF(SALIDAS!B:B,B32,SALIDAS!D:D) -> 0 | F32: =SUM(D32-E32) -> 4
B33: ROD-UC206-G | C33: =IFERROR(VLOOKUP(B33 ,INVENTARIO!B35:C1000,2,0),"") -> UC206G | D33: =SUMIF(ENTRADAS!B:B,B33,ENTRADAS!D:D) -> 4 | E33: =SUMIF(SALIDAS!B:B,B33,SALIDAS!D:D) -> 0 | F33: =SUM(D33-E33) -> 4
B34: ROD-UC204D1 | C34: =IFERROR(VLOOKUP(B34 ,INVENTARIO!B36:C1000,2,0),"") -> UC204D1 | D34: =SUMIF(ENTRADAS!B:B,B34,ENTRADAS!D:D) -> 11 | E34: =SUMIF(SALIDAS!B:B,B34,SALIDAS!D:D) -> 15 | F34: =SUM(D34-E34) -> -4
B35: ROD-AS204D1 | C35: =IFERROR(VLOOKUP(B35 ,INVENTARIO!B37:C1000,2,0),"") -> AS204D1 | D35: =SUMIF(ENTRADAS!B:B,B35,ENTRADAS!D:D) -> 4 | E35: =SUMIF(SALIDAS!B:B,B35,SALIDAS!D:D) -> 0 | F35: =SUM(D35-E35) -> 4
B36: ROD-UC202-010D1 | C36: =IFERROR(VLOOKUP(B36 ,INVENTARIO!B38:C1000,2,0),"") -> UC202-010D1 | D36: =SUMIF(ENTRADAS!B:B,B36,ENTRADAS!D:D) -> 10 | E36: =SUMIF(SALIDAS!B:B,B36,SALIDAS!D:D) -> 0 | F36: =SUM(D36-E36) -> 10
B37: ROD-UC211 | C37: =IFERROR(VLOOKUP(B37 ,INVENTARIO!B39:C1000,2,0),"") -> UC211-200D1 | D37: =SUMIF(ENTRADAS!B:B,B37,ENTRADAS!D:D) -> 6 | E37: =SUMIF(SALIDAS!B:B,B37,SALIDAS!D:D) -> 0 | F37: =SUM(D37-E37) -> 6
B38: ROD-UC212 | C38: =IFERROR(VLOOKUP(B38 ,INVENTARIO!B40:C1000,2,0),"") -> UC212D1 | D38: =SUMIF(ENTRADAS!B:B,B38,ENTRADAS!D:D) -> 2 | E38: =SUMIF(SALIDAS!B:B,B38,SALIDAS!D:D) -> 0 | F38: =SUM(D38-E38) -> 2
B39: ROD-UC205 | C39: =IFERROR(VLOOKUP(B39 ,INVENTARIO!B41:C1000,2,0),"") -> UC205 | D39: =SUMIF(ENTRADAS!B:B,B39,ENTRADAS!D:D) -> 36 | E39: =SUMIF(SALIDAS!B:B,B39,SALIDAS!D:D) -> 22 | F39: =SUM(D39-E39) -> 14
B40: ROD-UC208 | C40: =IFERROR(VLOOKUP(B40 ,INVENTARIO!B42:C1000,2,0),"") -> UC208-40MM | D40: =SUMIF(ENTRADAS!B:B,B40,ENTRADAS!D:D) -> 4 | E40: =SUMIF(SALIDAS!B:B,B40,SALIDAS!D:D) -> 0 | F40: =SUM(D40-E40) -> 4
B41: ROD-UC214 | C41: =IFERROR(VLOOKUP(B41 ,INVENTARIO!B43:C1000,2,0),"") -> UC214D1 | D41: =SUMIF(ENTRADAS!B:B,B41,ENTRADAS!D:D) -> 2 | E41: =SUMIF(SALIDAS!B:B,B41,SALIDAS!D:D) -> 0 | F41: =SUM(D41-E41) -> 2
...

Sheet datos recolectados
